[2024-12-02T09:37:49.804+0000] {local_task_job_runner.py:123} INFO - ::group::Pre task execution logs
[2024-12-02T09:37:49.824+0000] {taskinstance.py:2613} INFO - Dependencies all met for dep_context=non-requeueable deps ti=<TaskInstance: IMDB_testing_DAG.transform manual__2024-12-02T09:37:44.477733+00:00 [queued]>
[2024-12-02T09:37:49.836+0000] {taskinstance.py:2613} INFO - Dependencies all met for dep_context=requeueable deps ti=<TaskInstance: IMDB_testing_DAG.transform manual__2024-12-02T09:37:44.477733+00:00 [queued]>
[2024-12-02T09:37:49.837+0000] {taskinstance.py:2866} INFO - Starting attempt 1 of 3
[2024-12-02T09:37:49.855+0000] {taskinstance.py:2889} INFO - Executing <Task(PythonOperator): transform> on 2024-12-02 09:37:44.477733+00:00
[2024-12-02T09:37:49.870+0000] {logging_mixin.py:190} WARNING - /home/***/.local/lib/python3.12/site-packages/***/task/task_runner/standard_task_runner.py:70 DeprecationWarning: This process (pid=54409) is multi-threaded, use of fork() may lead to deadlocks in the child.
[2024-12-02T09:37:49.869+0000] {standard_task_runner.py:104} INFO - Running: ['***', 'tasks', 'run', 'IMDB_testing_DAG', 'transform', 'manual__2024-12-02T09:37:44.477733+00:00', '--job-id', '70', '--raw', '--subdir', 'DAGS_FOLDER/etl.py', '--cfg-path', '/tmp/tmp86qqt53_']
[2024-12-02T09:37:49.871+0000] {standard_task_runner.py:72} INFO - Started process 54425 to run task
[2024-12-02T09:37:49.871+0000] {standard_task_runner.py:105} INFO - Job 70: Subtask transform
[2024-12-02T09:37:49.923+0000] {task_command.py:467} INFO - Running <TaskInstance: IMDB_testing_DAG.transform manual__2024-12-02T09:37:44.477733+00:00 [running]> on host a34e3ee3c8c3
[2024-12-02T09:37:50.029+0000] {taskinstance.py:3132} INFO - Exporting env vars: AIRFLOW_CTX_DAG_OWNER='***' AIRFLOW_CTX_DAG_ID='IMDB_testing_DAG' AIRFLOW_CTX_TASK_ID='transform' AIRFLOW_CTX_EXECUTION_DATE='2024-12-02T09:37:44.477733+00:00' AIRFLOW_CTX_TRY_NUMBER='1' AIRFLOW_CTX_DAG_RUN_ID='manual__2024-12-02T09:37:44.477733+00:00'
[2024-12-02T09:37:50.031+0000] {logging_mixin.py:190} INFO - Task instance is in running state
[2024-12-02T09:37:50.032+0000] {logging_mixin.py:190} INFO -  Previous state of the Task instance: queued
[2024-12-02T09:37:50.033+0000] {logging_mixin.py:190} INFO - Current task name:transform state:running start_date:2024-12-02 09:37:49.825169+00:00
[2024-12-02T09:37:50.034+0000] {logging_mixin.py:190} INFO - Dag name:IMDB_testing_DAG and current dag run status:running
[2024-12-02T09:37:50.035+0000] {taskinstance.py:731} INFO - ::endgroup::
[2024-12-02T09:37:50.178+0000] {taskinstance.py:3311} ERROR - Task failed with exception
Traceback (most recent call last):
  File "/home/airflow/.local/lib/python3.12/site-packages/airflow/models/taskinstance.py", line 767, in _execute_task
    result = _execute_callable(context=context, **execute_callable_kwargs)
             ^^^^^^^^^^^^^^^^^^^^^^^^^^^^^^^^^^^^^^^^^^^^^^^^^^^^^^^^^^^^^
  File "/home/airflow/.local/lib/python3.12/site-packages/airflow/models/taskinstance.py", line 733, in _execute_callable
    return ExecutionCallableRunner(
           ^^^^^^^^^^^^^^^^^^^^^^^^
  File "/home/airflow/.local/lib/python3.12/site-packages/airflow/utils/operator_helpers.py", line 252, in run
    return self.func(*args, **kwargs)
           ^^^^^^^^^^^^^^^^^^^^^^^^^^
  File "/home/airflow/.local/lib/python3.12/site-packages/airflow/models/baseoperator.py", line 417, in wrapper
    return func(self, *args, **kwargs)
           ^^^^^^^^^^^^^^^^^^^^^^^^^^^
  File "/home/airflow/.local/lib/python3.12/site-packages/airflow/operators/python.py", line 238, in execute
    return_value = self.execute_callable()
                   ^^^^^^^^^^^^^^^^^^^^^^^
  File "/home/airflow/.local/lib/python3.12/site-packages/airflow/operators/python.py", line 256, in execute_callable
    return runner.run(*self.op_args, **self.op_kwargs)
           ^^^^^^^^^^^^^^^^^^^^^^^^^^^^^^^^^^^^^^^^^^^
  File "/home/airflow/.local/lib/python3.12/site-packages/airflow/utils/operator_helpers.py", line 252, in run
    return self.func(*args, **kwargs)
           ^^^^^^^^^^^^^^^^^^^^^^^^^^
  File "/opt/airflow/app/src/transform/transform.py", line 122, in transform
    fact_movie = create_fact_table(null_handled_df, dim_tables, merge_keys, drop_columns)
                 ^^^^^^^^^^^^^^^^^^^^^^^^^^^^^^^^^^^^^^^^^^^^^^^^^^^^^^^^^^^^^^^^^^^^^^^^
  File "/opt/airflow/app/src/transform/transform.py", line 87, in create_fact_table
    fact_table.drop(columns = [drop_columns],inplace = True)
  File "/home/airflow/.local/lib/python3.12/site-packages/pandas/core/frame.py", line 5344, in drop
    return super().drop(
           ^^^^^^^^^^^^^
  File "/home/airflow/.local/lib/python3.12/site-packages/pandas/core/generic.py", line 4711, in drop
    obj = obj._drop_axis(labels, axis, level=level, errors=errors)
          ^^^^^^^^^^^^^^^^^^^^^^^^^^^^^^^^^^^^^^^^^^^^^^^^^^^^^^^^
  File "/home/airflow/.local/lib/python3.12/site-packages/pandas/core/generic.py", line 4753, in _drop_axis
    new_axis = axis.drop(labels, errors=errors)
               ^^^^^^^^^^^^^^^^^^^^^^^^^^^^^^^^
  File "/home/airflow/.local/lib/python3.12/site-packages/pandas/core/indexes/base.py", line 7000, in drop
    raise KeyError(f"{labels[mask].tolist()} not found in axis")
KeyError: "[('title_x', 'type_x', 'certificate_rating_x', 'country', 'director', 'productionBudget_currency', 'worldwideGross_currency', 'genre', 'title_y', 'type_y', 'certificate_rating_y')] not found in axis"
[2024-12-02T09:37:50.206+0000] {logging_mixin.py:190} INFO - Task instance in failure state
[2024-12-02T09:37:50.207+0000] {logging_mixin.py:190} INFO - Task start:2024-12-02 09:37:49.825169+00:00 end:2024-12-02 09:37:50.205719+00:00 duration:0.38055
[2024-12-02T09:37:50.208+0000] {logging_mixin.py:190} INFO - Task:<Task(PythonOperator): transform> dag:<DAG: IMDB_testing_DAG> dagrun:<DagRun IMDB_testing_DAG @ 2024-12-02 09:37:44.477733+00:00: manual__2024-12-02T09:37:44.477733+00:00, state:running, queued_at: 2024-12-02 09:37:44.512805+00:00. externally triggered: True>
[2024-12-02T09:37:50.209+0000] {logging_mixin.py:190} INFO - Failure caused by "[('title_x', 'type_x', 'certificate_rating_x', 'country', 'director', 'productionBudget_currency', 'worldwideGross_currency', 'genre', 'title_y', 'type_y', 'certificate_rating_y')] not found in axis"
[2024-12-02T09:37:50.210+0000] {taskinstance.py:1225} INFO - Marking task as UP_FOR_RETRY. dag_id=IMDB_testing_DAG, task_id=transform, run_id=manual__2024-12-02T09:37:44.477733+00:00, execution_date=20241202T093744, start_date=20241202T093749, end_date=20241202T093750
[2024-12-02T09:37:50.231+0000] {taskinstance.py:340} INFO - ::group::Post task execution logs
[2024-12-02T09:37:50.232+0000] {standard_task_runner.py:124} ERROR - Failed to execute job 70 for task transform ("[('title_x', 'type_x', 'certificate_rating_x', 'country', 'director', 'productionBudget_currency', 'worldwideGross_currency', 'genre', 'title_y', 'type_y', 'certificate_rating_y')] not found in axis"; 54425)
Traceback (most recent call last):
  File "/home/airflow/.local/lib/python3.12/site-packages/airflow/task/task_runner/standard_task_runner.py", line 117, in _start_by_fork
    ret = args.func(args, dag=self.dag)
          ^^^^^^^^^^^^^^^^^^^^^^^^^^^^^
  File "/home/airflow/.local/lib/python3.12/site-packages/airflow/cli/cli_config.py", line 49, in command
    return func(*args, **kwargs)
           ^^^^^^^^^^^^^^^^^^^^^
  File "/home/airflow/.local/lib/python3.12/site-packages/airflow/utils/cli.py", line 116, in wrapper
    return f(*args, **kwargs)
           ^^^^^^^^^^^^^^^^^^
  File "/home/airflow/.local/lib/python3.12/site-packages/airflow/cli/commands/task_command.py", line 483, in task_run
    task_return_code = _run_task_by_selected_method(args, _dag, ti)
                       ^^^^^^^^^^^^^^^^^^^^^^^^^^^^^^^^^^^^^^^^^^^^
  File "/home/airflow/.local/lib/python3.12/site-packages/airflow/cli/commands/task_command.py", line 256, in _run_task_by_selected_method
    return _run_raw_task(args, ti)
           ^^^^^^^^^^^^^^^^^^^^^^^
  File "/home/airflow/.local/lib/python3.12/site-packages/airflow/cli/commands/task_command.py", line 341, in _run_raw_task
    return ti._run_raw_task(
           ^^^^^^^^^^^^^^^^^
  File "/home/airflow/.local/lib/python3.12/site-packages/airflow/utils/session.py", line 97, in wrapper
    return func(*args, session=session, **kwargs)
           ^^^^^^^^^^^^^^^^^^^^^^^^^^^^^^^^^^^^^^
  File "/home/airflow/.local/lib/python3.12/site-packages/airflow/models/taskinstance.py", line 3005, in _run_raw_task
    return _run_raw_task(
           ^^^^^^^^^^^^^^
  File "/home/airflow/.local/lib/python3.12/site-packages/airflow/models/taskinstance.py", line 273, in _run_raw_task
    TaskInstance._execute_task_with_callbacks(
  File "/home/airflow/.local/lib/python3.12/site-packages/airflow/models/taskinstance.py", line 3159, in _execute_task_with_callbacks
    result = self._execute_task(context, task_orig)
             ^^^^^^^^^^^^^^^^^^^^^^^^^^^^^^^^^^^^^^
  File "/home/airflow/.local/lib/python3.12/site-packages/airflow/models/taskinstance.py", line 3183, in _execute_task
    return _execute_task(self, context, task_orig)
           ^^^^^^^^^^^^^^^^^^^^^^^^^^^^^^^^^^^^^^^
  File "/home/airflow/.local/lib/python3.12/site-packages/airflow/models/taskinstance.py", line 767, in _execute_task
    result = _execute_callable(context=context, **execute_callable_kwargs)
             ^^^^^^^^^^^^^^^^^^^^^^^^^^^^^^^^^^^^^^^^^^^^^^^^^^^^^^^^^^^^^
  File "/home/airflow/.local/lib/python3.12/site-packages/airflow/models/taskinstance.py", line 733, in _execute_callable
    return ExecutionCallableRunner(
           ^^^^^^^^^^^^^^^^^^^^^^^^
  File "/home/airflow/.local/lib/python3.12/site-packages/airflow/utils/operator_helpers.py", line 252, in run
    return self.func(*args, **kwargs)
           ^^^^^^^^^^^^^^^^^^^^^^^^^^
  File "/home/airflow/.local/lib/python3.12/site-packages/airflow/models/baseoperator.py", line 417, in wrapper
    return func(self, *args, **kwargs)
           ^^^^^^^^^^^^^^^^^^^^^^^^^^^
  File "/home/airflow/.local/lib/python3.12/site-packages/airflow/operators/python.py", line 238, in execute
    return_value = self.execute_callable()
                   ^^^^^^^^^^^^^^^^^^^^^^^
  File "/home/airflow/.local/lib/python3.12/site-packages/airflow/operators/python.py", line 256, in execute_callable
    return runner.run(*self.op_args, **self.op_kwargs)
           ^^^^^^^^^^^^^^^^^^^^^^^^^^^^^^^^^^^^^^^^^^^
  File "/home/airflow/.local/lib/python3.12/site-packages/airflow/utils/operator_helpers.py", line 252, in run
    return self.func(*args, **kwargs)
           ^^^^^^^^^^^^^^^^^^^^^^^^^^
  File "/opt/airflow/app/src/transform/transform.py", line 122, in transform
    fact_movie = create_fact_table(null_handled_df, dim_tables, merge_keys, drop_columns)
                 ^^^^^^^^^^^^^^^^^^^^^^^^^^^^^^^^^^^^^^^^^^^^^^^^^^^^^^^^^^^^^^^^^^^^^^^^
  File "/opt/airflow/app/src/transform/transform.py", line 87, in create_fact_table
    fact_table.drop(columns = [drop_columns],inplace = True)
  File "/home/airflow/.local/lib/python3.12/site-packages/pandas/core/frame.py", line 5344, in drop
    return super().drop(
           ^^^^^^^^^^^^^
  File "/home/airflow/.local/lib/python3.12/site-packages/pandas/core/generic.py", line 4711, in drop
    obj = obj._drop_axis(labels, axis, level=level, errors=errors)
          ^^^^^^^^^^^^^^^^^^^^^^^^^^^^^^^^^^^^^^^^^^^^^^^^^^^^^^^^
  File "/home/airflow/.local/lib/python3.12/site-packages/pandas/core/generic.py", line 4753, in _drop_axis
    new_axis = axis.drop(labels, errors=errors)
               ^^^^^^^^^^^^^^^^^^^^^^^^^^^^^^^^
  File "/home/airflow/.local/lib/python3.12/site-packages/pandas/core/indexes/base.py", line 7000, in drop
    raise KeyError(f"{labels[mask].tolist()} not found in axis")
KeyError: "[('title_x', 'type_x', 'certificate_rating_x', 'country', 'director', 'productionBudget_currency', 'worldwideGross_currency', 'genre', 'title_y', 'type_y', 'certificate_rating_y')] not found in axis"
[2024-12-02T09:37:50.256+0000] {local_task_job_runner.py:266} INFO - Task exited with return code 1
[2024-12-02T09:37:50.282+0000] {taskinstance.py:3895} INFO - 0 downstream tasks scheduled from follow-on schedule check
[2024-12-02T09:37:50.286+0000] {local_task_job_runner.py:245} INFO - ::endgroup::
