[2024-12-02T05:37:52.222+0000] {local_task_job_runner.py:123} INFO - ::group::Pre task execution logs
[2024-12-02T05:37:52.250+0000] {taskinstance.py:2613} INFO - Dependencies all met for dep_context=non-requeueable deps ti=<TaskInstance: IMDB_DAG.transform scheduled__2024-12-01T00:00:00+00:00 [queued]>
[2024-12-02T05:37:52.265+0000] {taskinstance.py:2613} INFO - Dependencies all met for dep_context=requeueable deps ti=<TaskInstance: IMDB_DAG.transform scheduled__2024-12-01T00:00:00+00:00 [queued]>
[2024-12-02T05:37:52.266+0000] {taskinstance.py:2866} INFO - Starting attempt 1 of 3
[2024-12-02T05:37:52.292+0000] {taskinstance.py:2889} INFO - Executing <Task(PythonOperator): transform> on 2024-12-01 00:00:00+00:00
[2024-12-02T05:37:52.308+0000] {standard_task_runner.py:104} INFO - Running: ['***', 'tasks', 'run', 'IMDB_DAG', 'transform', 'scheduled__2024-12-01T00:00:00+00:00', '--job-id', '18', '--raw', '--subdir', 'DAGS_FOLDER/etl.py', '--cfg-path', '/tmp/tmp3d_lxtf7']
[2024-12-02T05:37:52.308+0000] {logging_mixin.py:190} WARNING - /home/***/.local/lib/python3.12/site-packages/***/task/task_runner/standard_task_runner.py:70 DeprecationWarning: This process (pid=7140) is multi-threaded, use of fork() may lead to deadlocks in the child.
[2024-12-02T05:37:52.311+0000] {standard_task_runner.py:105} INFO - Job 18: Subtask transform
[2024-12-02T05:37:52.311+0000] {standard_task_runner.py:72} INFO - Started process 7157 to run task
[2024-12-02T05:37:52.375+0000] {task_command.py:467} INFO - Running <TaskInstance: IMDB_DAG.transform scheduled__2024-12-01T00:00:00+00:00 [running]> on host 7907820bdc36
[2024-12-02T05:37:52.486+0000] {taskinstance.py:3132} INFO - Exporting env vars: AIRFLOW_CTX_DAG_OWNER='***' AIRFLOW_CTX_DAG_ID='IMDB_DAG' AIRFLOW_CTX_TASK_ID='transform' AIRFLOW_CTX_EXECUTION_DATE='2024-12-01T00:00:00+00:00' AIRFLOW_CTX_TRY_NUMBER='1' AIRFLOW_CTX_DAG_RUN_ID='scheduled__2024-12-01T00:00:00+00:00'
[2024-12-02T05:37:52.488+0000] {logging_mixin.py:190} INFO - Task instance is in running state
[2024-12-02T05:37:52.490+0000] {logging_mixin.py:190} INFO -  Previous state of the Task instance: queued
[2024-12-02T05:37:52.491+0000] {logging_mixin.py:190} INFO - Current task name:transform state:running start_date:2024-12-02 05:37:52.251162+00:00
[2024-12-02T05:37:52.491+0000] {logging_mixin.py:190} INFO - Dag name:IMDB_DAG and current dag run status:running
[2024-12-02T05:37:52.492+0000] {taskinstance.py:731} INFO - ::endgroup::
[2024-12-02T05:37:52.641+0000] {taskinstance.py:3311} ERROR - Task failed with exception
Traceback (most recent call last):
  File "/home/airflow/.local/lib/python3.12/site-packages/sqlalchemy/engine/base.py", line 1910, in _execute_context
    self.dialect.do_execute(
  File "/home/airflow/.local/lib/python3.12/site-packages/sqlalchemy/engine/default.py", line 736, in do_execute
    cursor.execute(statement, parameters)
psycopg2.errors.UndefinedTable: relation "staging_area" does not exist
LINE 3:             FROM staging_area
                         ^


The above exception was the direct cause of the following exception:

Traceback (most recent call last):
  File "/home/airflow/.local/lib/python3.12/site-packages/airflow/models/taskinstance.py", line 767, in _execute_task
    result = _execute_callable(context=context, **execute_callable_kwargs)
             ^^^^^^^^^^^^^^^^^^^^^^^^^^^^^^^^^^^^^^^^^^^^^^^^^^^^^^^^^^^^^
  File "/home/airflow/.local/lib/python3.12/site-packages/airflow/models/taskinstance.py", line 733, in _execute_callable
    return ExecutionCallableRunner(
           ^^^^^^^^^^^^^^^^^^^^^^^^
  File "/home/airflow/.local/lib/python3.12/site-packages/airflow/utils/operator_helpers.py", line 252, in run
    return self.func(*args, **kwargs)
           ^^^^^^^^^^^^^^^^^^^^^^^^^^
  File "/home/airflow/.local/lib/python3.12/site-packages/airflow/models/baseoperator.py", line 417, in wrapper
    return func(self, *args, **kwargs)
           ^^^^^^^^^^^^^^^^^^^^^^^^^^^
  File "/home/airflow/.local/lib/python3.12/site-packages/airflow/operators/python.py", line 238, in execute
    return_value = self.execute_callable()
                   ^^^^^^^^^^^^^^^^^^^^^^^
  File "/home/airflow/.local/lib/python3.12/site-packages/airflow/operators/python.py", line 256, in execute_callable
    return runner.run(*self.op_args, **self.op_kwargs)
           ^^^^^^^^^^^^^^^^^^^^^^^^^^^^^^^^^^^^^^^^^^^
  File "/home/airflow/.local/lib/python3.12/site-packages/airflow/utils/operator_helpers.py", line 252, in run
    return self.func(*args, **kwargs)
           ^^^^^^^^^^^^^^^^^^^^^^^^^^
  File "/opt/airflow/app/src/transform/transform.py", line 104, in transform
    df = pd.read_sql(query,con= engine)
         ^^^^^^^^^^^^^^^^^^^^^^^^^^^^^^
  File "/home/airflow/.local/lib/python3.12/site-packages/pandas/io/sql.py", line 682, in read_sql
    return pandas_sql.read_query(
           ^^^^^^^^^^^^^^^^^^^^^^
  File "/home/airflow/.local/lib/python3.12/site-packages/pandas/io/sql.py", line 1776, in read_query
    result = self.execute(sql, params)
             ^^^^^^^^^^^^^^^^^^^^^^^^^
  File "/home/airflow/.local/lib/python3.12/site-packages/pandas/io/sql.py", line 1599, in execute
    return self.con.exec_driver_sql(sql, *args)
           ^^^^^^^^^^^^^^^^^^^^^^^^^^^^^^^^^^^^
  File "/home/airflow/.local/lib/python3.12/site-packages/sqlalchemy/engine/base.py", line 1770, in exec_driver_sql
    return self._exec_driver_sql(
           ^^^^^^^^^^^^^^^^^^^^^^
  File "/home/airflow/.local/lib/python3.12/site-packages/sqlalchemy/engine/base.py", line 1674, in _exec_driver_sql
    ret = self._execute_context(
          ^^^^^^^^^^^^^^^^^^^^^^
  File "/home/airflow/.local/lib/python3.12/site-packages/sqlalchemy/engine/base.py", line 1953, in _execute_context
    self._handle_dbapi_exception(
  File "/home/airflow/.local/lib/python3.12/site-packages/sqlalchemy/engine/base.py", line 2134, in _handle_dbapi_exception
    util.raise_(
  File "/home/airflow/.local/lib/python3.12/site-packages/sqlalchemy/util/compat.py", line 211, in raise_
    raise exception
  File "/home/airflow/.local/lib/python3.12/site-packages/sqlalchemy/engine/base.py", line 1910, in _execute_context
    self.dialect.do_execute(
  File "/home/airflow/.local/lib/python3.12/site-packages/sqlalchemy/engine/default.py", line 736, in do_execute
    cursor.execute(statement, parameters)
sqlalchemy.exc.ProgrammingError: (psycopg2.errors.UndefinedTable) relation "staging_area" does not exist
LINE 3:             FROM staging_area
                         ^

[SQL: 
            SELECT * 
            FROM staging_area
            WHERE created_at = (
            SELECT MAX(created_at) 
            FROM staging_area 
            )]
(Background on this error at: https://sqlalche.me/e/14/f405)
[2024-12-02T05:37:52.666+0000] {logging_mixin.py:190} INFO - Task instance in failure state
[2024-12-02T05:37:52.666+0000] {logging_mixin.py:190} INFO - Task start:2024-12-02 05:37:52.251162+00:00 end:2024-12-02 05:37:52.665508+00:00 duration:0.414346
[2024-12-02T05:37:52.667+0000] {logging_mixin.py:190} INFO - Task:<Task(PythonOperator): transform> dag:<DAG: IMDB_DAG> dagrun:<DagRun IMDB_DAG @ 2024-12-01 00:00:00+00:00: scheduled__2024-12-01T00:00:00+00:00, state:running, queued_at: 2024-12-02 05:37:41.024770+00:00. externally triggered: False>
[2024-12-02T05:37:52.668+0000] {logging_mixin.py:190} INFO - Failure caused by (psycopg2.errors.UndefinedTable) relation "staging_area" does not exist
LINE 3:             FROM staging_area
                         ^

[SQL: 
            SELECT * 
            FROM staging_area
            WHERE created_at = (
            SELECT MAX(created_at) 
            FROM staging_area 
            )]
(Background on this error at: https://sqlalche.me/e/14/f405)
[2024-12-02T05:37:52.669+0000] {taskinstance.py:1225} INFO - Marking task as UP_FOR_RETRY. dag_id=IMDB_DAG, task_id=transform, run_id=scheduled__2024-12-01T00:00:00+00:00, execution_date=20241201T000000, start_date=20241202T053752, end_date=20241202T053752
[2024-12-02T05:37:52.699+0000] {taskinstance.py:340} INFO - ::group::Post task execution logs
[2024-12-02T05:37:52.700+0000] {standard_task_runner.py:124} ERROR - Failed to execute job 18 for task transform ((psycopg2.errors.UndefinedTable) relation "staging_area" does not exist
LINE 3:             FROM staging_area
                         ^

[SQL: 
            SELECT * 
            FROM staging_area
            WHERE created_at = (
            SELECT MAX(created_at) 
            FROM staging_area 
            )]
(Background on this error at: https://sqlalche.me/e/14/f405); 7157)
Traceback (most recent call last):
  File "/home/airflow/.local/lib/python3.12/site-packages/sqlalchemy/engine/base.py", line 1910, in _execute_context
    self.dialect.do_execute(
  File "/home/airflow/.local/lib/python3.12/site-packages/sqlalchemy/engine/default.py", line 736, in do_execute
    cursor.execute(statement, parameters)
psycopg2.errors.UndefinedTable: relation "staging_area" does not exist
LINE 3:             FROM staging_area
                         ^


The above exception was the direct cause of the following exception:

Traceback (most recent call last):
  File "/home/airflow/.local/lib/python3.12/site-packages/airflow/task/task_runner/standard_task_runner.py", line 117, in _start_by_fork
    ret = args.func(args, dag=self.dag)
          ^^^^^^^^^^^^^^^^^^^^^^^^^^^^^
  File "/home/airflow/.local/lib/python3.12/site-packages/airflow/cli/cli_config.py", line 49, in command
    return func(*args, **kwargs)
           ^^^^^^^^^^^^^^^^^^^^^
  File "/home/airflow/.local/lib/python3.12/site-packages/airflow/utils/cli.py", line 116, in wrapper
    return f(*args, **kwargs)
           ^^^^^^^^^^^^^^^^^^
  File "/home/airflow/.local/lib/python3.12/site-packages/airflow/cli/commands/task_command.py", line 483, in task_run
    task_return_code = _run_task_by_selected_method(args, _dag, ti)
                       ^^^^^^^^^^^^^^^^^^^^^^^^^^^^^^^^^^^^^^^^^^^^
  File "/home/airflow/.local/lib/python3.12/site-packages/airflow/cli/commands/task_command.py", line 256, in _run_task_by_selected_method
    return _run_raw_task(args, ti)
           ^^^^^^^^^^^^^^^^^^^^^^^
  File "/home/airflow/.local/lib/python3.12/site-packages/airflow/cli/commands/task_command.py", line 341, in _run_raw_task
    return ti._run_raw_task(
           ^^^^^^^^^^^^^^^^^
  File "/home/airflow/.local/lib/python3.12/site-packages/airflow/utils/session.py", line 97, in wrapper
    return func(*args, session=session, **kwargs)
           ^^^^^^^^^^^^^^^^^^^^^^^^^^^^^^^^^^^^^^
  File "/home/airflow/.local/lib/python3.12/site-packages/airflow/models/taskinstance.py", line 3005, in _run_raw_task
    return _run_raw_task(
           ^^^^^^^^^^^^^^
  File "/home/airflow/.local/lib/python3.12/site-packages/airflow/models/taskinstance.py", line 273, in _run_raw_task
    TaskInstance._execute_task_with_callbacks(
  File "/home/airflow/.local/lib/python3.12/site-packages/airflow/models/taskinstance.py", line 3159, in _execute_task_with_callbacks
    result = self._execute_task(context, task_orig)
             ^^^^^^^^^^^^^^^^^^^^^^^^^^^^^^^^^^^^^^
  File "/home/airflow/.local/lib/python3.12/site-packages/airflow/models/taskinstance.py", line 3183, in _execute_task
    return _execute_task(self, context, task_orig)
           ^^^^^^^^^^^^^^^^^^^^^^^^^^^^^^^^^^^^^^^
  File "/home/airflow/.local/lib/python3.12/site-packages/airflow/models/taskinstance.py", line 767, in _execute_task
    result = _execute_callable(context=context, **execute_callable_kwargs)
             ^^^^^^^^^^^^^^^^^^^^^^^^^^^^^^^^^^^^^^^^^^^^^^^^^^^^^^^^^^^^^
  File "/home/airflow/.local/lib/python3.12/site-packages/airflow/models/taskinstance.py", line 733, in _execute_callable
    return ExecutionCallableRunner(
           ^^^^^^^^^^^^^^^^^^^^^^^^
  File "/home/airflow/.local/lib/python3.12/site-packages/airflow/utils/operator_helpers.py", line 252, in run
    return self.func(*args, **kwargs)
           ^^^^^^^^^^^^^^^^^^^^^^^^^^
  File "/home/airflow/.local/lib/python3.12/site-packages/airflow/models/baseoperator.py", line 417, in wrapper
    return func(self, *args, **kwargs)
           ^^^^^^^^^^^^^^^^^^^^^^^^^^^
  File "/home/airflow/.local/lib/python3.12/site-packages/airflow/operators/python.py", line 238, in execute
    return_value = self.execute_callable()
                   ^^^^^^^^^^^^^^^^^^^^^^^
  File "/home/airflow/.local/lib/python3.12/site-packages/airflow/operators/python.py", line 256, in execute_callable
    return runner.run(*self.op_args, **self.op_kwargs)
           ^^^^^^^^^^^^^^^^^^^^^^^^^^^^^^^^^^^^^^^^^^^
  File "/home/airflow/.local/lib/python3.12/site-packages/airflow/utils/operator_helpers.py", line 252, in run
    return self.func(*args, **kwargs)
           ^^^^^^^^^^^^^^^^^^^^^^^^^^
  File "/opt/airflow/app/src/transform/transform.py", line 104, in transform
    df = pd.read_sql(query,con= engine)
         ^^^^^^^^^^^^^^^^^^^^^^^^^^^^^^
  File "/home/airflow/.local/lib/python3.12/site-packages/pandas/io/sql.py", line 682, in read_sql
    return pandas_sql.read_query(
           ^^^^^^^^^^^^^^^^^^^^^^
  File "/home/airflow/.local/lib/python3.12/site-packages/pandas/io/sql.py", line 1776, in read_query
    result = self.execute(sql, params)
             ^^^^^^^^^^^^^^^^^^^^^^^^^
  File "/home/airflow/.local/lib/python3.12/site-packages/pandas/io/sql.py", line 1599, in execute
    return self.con.exec_driver_sql(sql, *args)
           ^^^^^^^^^^^^^^^^^^^^^^^^^^^^^^^^^^^^
  File "/home/airflow/.local/lib/python3.12/site-packages/sqlalchemy/engine/base.py", line 1770, in exec_driver_sql
    return self._exec_driver_sql(
           ^^^^^^^^^^^^^^^^^^^^^^
  File "/home/airflow/.local/lib/python3.12/site-packages/sqlalchemy/engine/base.py", line 1674, in _exec_driver_sql
    ret = self._execute_context(
          ^^^^^^^^^^^^^^^^^^^^^^
  File "/home/airflow/.local/lib/python3.12/site-packages/sqlalchemy/engine/base.py", line 1953, in _execute_context
    self._handle_dbapi_exception(
  File "/home/airflow/.local/lib/python3.12/site-packages/sqlalchemy/engine/base.py", line 2134, in _handle_dbapi_exception
    util.raise_(
  File "/home/airflow/.local/lib/python3.12/site-packages/sqlalchemy/util/compat.py", line 211, in raise_
    raise exception
  File "/home/airflow/.local/lib/python3.12/site-packages/sqlalchemy/engine/base.py", line 1910, in _execute_context
    self.dialect.do_execute(
  File "/home/airflow/.local/lib/python3.12/site-packages/sqlalchemy/engine/default.py", line 736, in do_execute
    cursor.execute(statement, parameters)
sqlalchemy.exc.ProgrammingError: (psycopg2.errors.UndefinedTable) relation "staging_area" does not exist
LINE 3:             FROM staging_area
                         ^

[SQL: 
            SELECT * 
            FROM staging_area
            WHERE created_at = (
            SELECT MAX(created_at) 
            FROM staging_area 
            )]
(Background on this error at: https://sqlalche.me/e/14/f405)
[2024-12-02T05:37:52.732+0000] {local_task_job_runner.py:266} INFO - Task exited with return code 1
[2024-12-02T05:37:52.782+0000] {taskinstance.py:3895} INFO - 0 downstream tasks scheduled from follow-on schedule check
[2024-12-02T05:37:52.786+0000] {local_task_job_runner.py:245} INFO - ::endgroup::
[2024-12-02T05:44:18.271+0000] {local_task_job_runner.py:123} INFO - ::group::Pre task execution logs
[2024-12-02T05:44:18.338+0000] {taskinstance.py:2613} INFO - Dependencies all met for dep_context=non-requeueable deps ti=<TaskInstance: IMDB_DAG.transform scheduled__2024-12-01T00:00:00+00:00 [queued]>
[2024-12-02T05:44:18.372+0000] {taskinstance.py:2613} INFO - Dependencies all met for dep_context=requeueable deps ti=<TaskInstance: IMDB_DAG.transform scheduled__2024-12-01T00:00:00+00:00 [queued]>
[2024-12-02T05:44:18.373+0000] {taskinstance.py:2866} INFO - Starting attempt 1 of 3
[2024-12-02T05:44:18.440+0000] {taskinstance.py:2889} INFO - Executing <Task(PythonOperator): transform> on 2024-12-01 00:00:00+00:00
[2024-12-02T05:44:18.533+0000] {logging_mixin.py:190} WARNING - /home/***/.local/lib/python3.12/site-packages/***/task/task_runner/standard_task_runner.py:70 DeprecationWarning: This process (pid=10778) is multi-threaded, use of fork() may lead to deadlocks in the child.
[2024-12-02T05:44:18.541+0000] {standard_task_runner.py:104} INFO - Running: ['***', 'tasks', 'run', 'IMDB_DAG', 'transform', 'scheduled__2024-12-01T00:00:00+00:00', '--job-id', '26', '--raw', '--subdir', 'DAGS_FOLDER/etl.py', '--cfg-path', '/tmp/tmpoq7q065c']
[2024-12-02T05:44:18.543+0000] {standard_task_runner.py:72} INFO - Started process 10802 to run task
[2024-12-02T05:44:18.544+0000] {standard_task_runner.py:105} INFO - Job 26: Subtask transform
[2024-12-02T05:44:19.015+0000] {task_command.py:467} INFO - Running <TaskInstance: IMDB_DAG.transform scheduled__2024-12-01T00:00:00+00:00 [running]> on host 7907820bdc36
[2024-12-02T05:44:19.687+0000] {taskinstance.py:3132} INFO - Exporting env vars: AIRFLOW_CTX_DAG_OWNER='***' AIRFLOW_CTX_DAG_ID='IMDB_DAG' AIRFLOW_CTX_TASK_ID='transform' AIRFLOW_CTX_EXECUTION_DATE='2024-12-01T00:00:00+00:00' AIRFLOW_CTX_TRY_NUMBER='1' AIRFLOW_CTX_DAG_RUN_ID='scheduled__2024-12-01T00:00:00+00:00'
[2024-12-02T05:44:19.691+0000] {logging_mixin.py:190} INFO - Task instance is in running state
[2024-12-02T05:44:19.693+0000] {logging_mixin.py:190} INFO -  Previous state of the Task instance: queued
[2024-12-02T05:44:19.694+0000] {logging_mixin.py:190} INFO - Current task name:transform state:running start_date:2024-12-02 05:44:18.340391+00:00
[2024-12-02T05:44:19.695+0000] {logging_mixin.py:190} INFO - Dag name:IMDB_DAG and current dag run status:running
[2024-12-02T05:44:19.697+0000] {taskinstance.py:731} INFO - ::endgroup::
[2024-12-02T05:44:20.343+0000] {taskinstance.py:3311} ERROR - Task failed with exception
Traceback (most recent call last):
  File "/home/airflow/.local/lib/python3.12/site-packages/sqlalchemy/engine/base.py", line 1910, in _execute_context
    self.dialect.do_execute(
  File "/home/airflow/.local/lib/python3.12/site-packages/sqlalchemy/engine/default.py", line 736, in do_execute
    cursor.execute(statement, parameters)
psycopg2.errors.UndefinedTable: relation "staging_area" does not exist
LINE 3:             FROM staging_area
                         ^


The above exception was the direct cause of the following exception:

Traceback (most recent call last):
  File "/home/airflow/.local/lib/python3.12/site-packages/airflow/models/taskinstance.py", line 767, in _execute_task
    result = _execute_callable(context=context, **execute_callable_kwargs)
             ^^^^^^^^^^^^^^^^^^^^^^^^^^^^^^^^^^^^^^^^^^^^^^^^^^^^^^^^^^^^^
  File "/home/airflow/.local/lib/python3.12/site-packages/airflow/models/taskinstance.py", line 733, in _execute_callable
    return ExecutionCallableRunner(
           ^^^^^^^^^^^^^^^^^^^^^^^^
  File "/home/airflow/.local/lib/python3.12/site-packages/airflow/utils/operator_helpers.py", line 252, in run
    return self.func(*args, **kwargs)
           ^^^^^^^^^^^^^^^^^^^^^^^^^^
  File "/home/airflow/.local/lib/python3.12/site-packages/airflow/models/baseoperator.py", line 417, in wrapper
    return func(self, *args, **kwargs)
           ^^^^^^^^^^^^^^^^^^^^^^^^^^^
  File "/home/airflow/.local/lib/python3.12/site-packages/airflow/operators/python.py", line 238, in execute
    return_value = self.execute_callable()
                   ^^^^^^^^^^^^^^^^^^^^^^^
  File "/home/airflow/.local/lib/python3.12/site-packages/airflow/operators/python.py", line 256, in execute_callable
    return runner.run(*self.op_args, **self.op_kwargs)
           ^^^^^^^^^^^^^^^^^^^^^^^^^^^^^^^^^^^^^^^^^^^
  File "/home/airflow/.local/lib/python3.12/site-packages/airflow/utils/operator_helpers.py", line 252, in run
    return self.func(*args, **kwargs)
           ^^^^^^^^^^^^^^^^^^^^^^^^^^
  File "/opt/airflow/app/src/transform/transform.py", line 104, in transform
    df = pd.read_sql(query,con= engine)
         ^^^^^^^^^^^^^^^^^^^^^^^^^^^^^^
  File "/home/airflow/.local/lib/python3.12/site-packages/pandas/io/sql.py", line 682, in read_sql
    return pandas_sql.read_query(
           ^^^^^^^^^^^^^^^^^^^^^^
  File "/home/airflow/.local/lib/python3.12/site-packages/pandas/io/sql.py", line 1776, in read_query
    result = self.execute(sql, params)
             ^^^^^^^^^^^^^^^^^^^^^^^^^
  File "/home/airflow/.local/lib/python3.12/site-packages/pandas/io/sql.py", line 1599, in execute
    return self.con.exec_driver_sql(sql, *args)
           ^^^^^^^^^^^^^^^^^^^^^^^^^^^^^^^^^^^^
  File "/home/airflow/.local/lib/python3.12/site-packages/sqlalchemy/engine/base.py", line 1770, in exec_driver_sql
    return self._exec_driver_sql(
           ^^^^^^^^^^^^^^^^^^^^^^
  File "/home/airflow/.local/lib/python3.12/site-packages/sqlalchemy/engine/base.py", line 1674, in _exec_driver_sql
    ret = self._execute_context(
          ^^^^^^^^^^^^^^^^^^^^^^
  File "/home/airflow/.local/lib/python3.12/site-packages/sqlalchemy/engine/base.py", line 1953, in _execute_context
    self._handle_dbapi_exception(
  File "/home/airflow/.local/lib/python3.12/site-packages/sqlalchemy/engine/base.py", line 2134, in _handle_dbapi_exception
    util.raise_(
  File "/home/airflow/.local/lib/python3.12/site-packages/sqlalchemy/util/compat.py", line 211, in raise_
    raise exception
  File "/home/airflow/.local/lib/python3.12/site-packages/sqlalchemy/engine/base.py", line 1910, in _execute_context
    self.dialect.do_execute(
  File "/home/airflow/.local/lib/python3.12/site-packages/sqlalchemy/engine/default.py", line 736, in do_execute
    cursor.execute(statement, parameters)
sqlalchemy.exc.ProgrammingError: (psycopg2.errors.UndefinedTable) relation "staging_area" does not exist
LINE 3:             FROM staging_area
                         ^

[SQL: 
            SELECT * 
            FROM staging_area
            WHERE created_at = (
            SELECT MAX(created_at) 
            FROM staging_area 
            )]
(Background on this error at: https://sqlalche.me/e/14/f405)
[2024-12-02T05:44:20.439+0000] {logging_mixin.py:190} INFO - Task instance in failure state
[2024-12-02T05:44:20.442+0000] {logging_mixin.py:190} INFO - Task start:2024-12-02 05:44:18.340391+00:00 end:2024-12-02 05:44:20.438239+00:00 duration:2.097848
[2024-12-02T05:44:20.444+0000] {logging_mixin.py:190} INFO - Task:<Task(PythonOperator): transform> dag:<DAG: IMDB_DAG> dagrun:<DagRun IMDB_DAG @ 2024-12-01 00:00:00+00:00: scheduled__2024-12-01T00:00:00+00:00, state:running, queued_at: 2024-12-02 05:44:04.816422+00:00. externally triggered: False>
[2024-12-02T05:44:20.446+0000] {logging_mixin.py:190} INFO - Failure caused by (psycopg2.errors.UndefinedTable) relation "staging_area" does not exist
LINE 3:             FROM staging_area
                         ^

[SQL: 
            SELECT * 
            FROM staging_area
            WHERE created_at = (
            SELECT MAX(created_at) 
            FROM staging_area 
            )]
(Background on this error at: https://sqlalche.me/e/14/f405)
[2024-12-02T05:44:20.449+0000] {taskinstance.py:1225} INFO - Marking task as UP_FOR_RETRY. dag_id=IMDB_DAG, task_id=transform, run_id=scheduled__2024-12-01T00:00:00+00:00, execution_date=20241201T000000, start_date=20241202T054418, end_date=20241202T054420
[2024-12-02T05:44:20.558+0000] {taskinstance.py:340} INFO - ::group::Post task execution logs
[2024-12-02T05:44:20.561+0000] {standard_task_runner.py:124} ERROR - Failed to execute job 26 for task transform ((psycopg2.errors.UndefinedTable) relation "staging_area" does not exist
LINE 3:             FROM staging_area
                         ^

[SQL: 
            SELECT * 
            FROM staging_area
            WHERE created_at = (
            SELECT MAX(created_at) 
            FROM staging_area 
            )]
(Background on this error at: https://sqlalche.me/e/14/f405); 10802)
Traceback (most recent call last):
  File "/home/airflow/.local/lib/python3.12/site-packages/sqlalchemy/engine/base.py", line 1910, in _execute_context
    self.dialect.do_execute(
  File "/home/airflow/.local/lib/python3.12/site-packages/sqlalchemy/engine/default.py", line 736, in do_execute
    cursor.execute(statement, parameters)
psycopg2.errors.UndefinedTable: relation "staging_area" does not exist
LINE 3:             FROM staging_area
                         ^


The above exception was the direct cause of the following exception:

Traceback (most recent call last):
  File "/home/airflow/.local/lib/python3.12/site-packages/airflow/task/task_runner/standard_task_runner.py", line 117, in _start_by_fork
    ret = args.func(args, dag=self.dag)
          ^^^^^^^^^^^^^^^^^^^^^^^^^^^^^
  File "/home/airflow/.local/lib/python3.12/site-packages/airflow/cli/cli_config.py", line 49, in command
    return func(*args, **kwargs)
           ^^^^^^^^^^^^^^^^^^^^^
  File "/home/airflow/.local/lib/python3.12/site-packages/airflow/utils/cli.py", line 116, in wrapper
    return f(*args, **kwargs)
           ^^^^^^^^^^^^^^^^^^
  File "/home/airflow/.local/lib/python3.12/site-packages/airflow/cli/commands/task_command.py", line 483, in task_run
    task_return_code = _run_task_by_selected_method(args, _dag, ti)
                       ^^^^^^^^^^^^^^^^^^^^^^^^^^^^^^^^^^^^^^^^^^^^
  File "/home/airflow/.local/lib/python3.12/site-packages/airflow/cli/commands/task_command.py", line 256, in _run_task_by_selected_method
    return _run_raw_task(args, ti)
           ^^^^^^^^^^^^^^^^^^^^^^^
  File "/home/airflow/.local/lib/python3.12/site-packages/airflow/cli/commands/task_command.py", line 341, in _run_raw_task
    return ti._run_raw_task(
           ^^^^^^^^^^^^^^^^^
  File "/home/airflow/.local/lib/python3.12/site-packages/airflow/utils/session.py", line 97, in wrapper
    return func(*args, session=session, **kwargs)
           ^^^^^^^^^^^^^^^^^^^^^^^^^^^^^^^^^^^^^^
  File "/home/airflow/.local/lib/python3.12/site-packages/airflow/models/taskinstance.py", line 3005, in _run_raw_task
    return _run_raw_task(
           ^^^^^^^^^^^^^^
  File "/home/airflow/.local/lib/python3.12/site-packages/airflow/models/taskinstance.py", line 273, in _run_raw_task
    TaskInstance._execute_task_with_callbacks(
  File "/home/airflow/.local/lib/python3.12/site-packages/airflow/models/taskinstance.py", line 3159, in _execute_task_with_callbacks
    result = self._execute_task(context, task_orig)
             ^^^^^^^^^^^^^^^^^^^^^^^^^^^^^^^^^^^^^^
  File "/home/airflow/.local/lib/python3.12/site-packages/airflow/models/taskinstance.py", line 3183, in _execute_task
    return _execute_task(self, context, task_orig)
           ^^^^^^^^^^^^^^^^^^^^^^^^^^^^^^^^^^^^^^^
  File "/home/airflow/.local/lib/python3.12/site-packages/airflow/models/taskinstance.py", line 767, in _execute_task
    result = _execute_callable(context=context, **execute_callable_kwargs)
             ^^^^^^^^^^^^^^^^^^^^^^^^^^^^^^^^^^^^^^^^^^^^^^^^^^^^^^^^^^^^^
  File "/home/airflow/.local/lib/python3.12/site-packages/airflow/models/taskinstance.py", line 733, in _execute_callable
    return ExecutionCallableRunner(
           ^^^^^^^^^^^^^^^^^^^^^^^^
  File "/home/airflow/.local/lib/python3.12/site-packages/airflow/utils/operator_helpers.py", line 252, in run
    return self.func(*args, **kwargs)
           ^^^^^^^^^^^^^^^^^^^^^^^^^^
  File "/home/airflow/.local/lib/python3.12/site-packages/airflow/models/baseoperator.py", line 417, in wrapper
    return func(self, *args, **kwargs)
           ^^^^^^^^^^^^^^^^^^^^^^^^^^^
  File "/home/airflow/.local/lib/python3.12/site-packages/airflow/operators/python.py", line 238, in execute
    return_value = self.execute_callable()
                   ^^^^^^^^^^^^^^^^^^^^^^^
  File "/home/airflow/.local/lib/python3.12/site-packages/airflow/operators/python.py", line 256, in execute_callable
    return runner.run(*self.op_args, **self.op_kwargs)
           ^^^^^^^^^^^^^^^^^^^^^^^^^^^^^^^^^^^^^^^^^^^
  File "/home/airflow/.local/lib/python3.12/site-packages/airflow/utils/operator_helpers.py", line 252, in run
    return self.func(*args, **kwargs)
           ^^^^^^^^^^^^^^^^^^^^^^^^^^
  File "/opt/airflow/app/src/transform/transform.py", line 104, in transform
    df = pd.read_sql(query,con= engine)
         ^^^^^^^^^^^^^^^^^^^^^^^^^^^^^^
  File "/home/airflow/.local/lib/python3.12/site-packages/pandas/io/sql.py", line 682, in read_sql
    return pandas_sql.read_query(
           ^^^^^^^^^^^^^^^^^^^^^^
  File "/home/airflow/.local/lib/python3.12/site-packages/pandas/io/sql.py", line 1776, in read_query
    result = self.execute(sql, params)
             ^^^^^^^^^^^^^^^^^^^^^^^^^
  File "/home/airflow/.local/lib/python3.12/site-packages/pandas/io/sql.py", line 1599, in execute
    return self.con.exec_driver_sql(sql, *args)
           ^^^^^^^^^^^^^^^^^^^^^^^^^^^^^^^^^^^^
  File "/home/airflow/.local/lib/python3.12/site-packages/sqlalchemy/engine/base.py", line 1770, in exec_driver_sql
    return self._exec_driver_sql(
           ^^^^^^^^^^^^^^^^^^^^^^
  File "/home/airflow/.local/lib/python3.12/site-packages/sqlalchemy/engine/base.py", line 1674, in _exec_driver_sql
    ret = self._execute_context(
          ^^^^^^^^^^^^^^^^^^^^^^
  File "/home/airflow/.local/lib/python3.12/site-packages/sqlalchemy/engine/base.py", line 1953, in _execute_context
    self._handle_dbapi_exception(
  File "/home/airflow/.local/lib/python3.12/site-packages/sqlalchemy/engine/base.py", line 2134, in _handle_dbapi_exception
    util.raise_(
  File "/home/airflow/.local/lib/python3.12/site-packages/sqlalchemy/util/compat.py", line 211, in raise_
    raise exception
  File "/home/airflow/.local/lib/python3.12/site-packages/sqlalchemy/engine/base.py", line 1910, in _execute_context
    self.dialect.do_execute(
  File "/home/airflow/.local/lib/python3.12/site-packages/sqlalchemy/engine/default.py", line 736, in do_execute
    cursor.execute(statement, parameters)
sqlalchemy.exc.ProgrammingError: (psycopg2.errors.UndefinedTable) relation "staging_area" does not exist
LINE 3:             FROM staging_area
                         ^

[SQL: 
            SELECT * 
            FROM staging_area
            WHERE created_at = (
            SELECT MAX(created_at) 
            FROM staging_area 
            )]
(Background on this error at: https://sqlalche.me/e/14/f405)
[2024-12-02T05:44:20.689+0000] {local_task_job_runner.py:266} INFO - Task exited with return code 1
[2024-12-02T05:44:20.733+0000] {local_task_job_runner.py:245} INFO - ::endgroup::
